Workbook
Name tgr: DCF!#REF!
Name wacc: DCF!#REF!

Sheet DCF
C3: Company: | D3: #VALUE!
C4: Ticker: | D4: {=_FV(D3,"Ticker symbol",TRUE)} -> PEP | F4: Today's Share Price: | H4: 142.62 | J4: WACC | K4: 0.065618938 | M4: Selected case: | N4: 2
C5: Date: | D5: =TODAY() -> 46153 | F5: Implied Share Price: | H5: =N45 -> 165.77642 | J5: TGR | K5: 0.03 | M5: Case 1: Very Optimistic
F6: Upside/(Downside) | H6: =H5/H4-1 -> 0.16236444 | M6: Case 2: Base
M7: Case 3: Very Pessimistic
C10: $ in Millions | J10: 1 | K10: =J10+1 -> 2 | L10: =K10+1 -> 3 | M10: =L10+1 -> 4 | N10: =M10+1 -> 5
C11: DCF | E11: 2021 | F11: =E11+1 -> 2022 | G11: =F11+1 -> 2023 | H11: =G11+1 -> 2024 | J11: =H11+1 -> 2025 | K11: =J11+1 -> 2026 | L11: =K11+1 -> 2027 | M11: =L11+1 -> 2028 | N11: =M11+1 -> 2029
C12: Revenue | E12: ='P&L Assumptions'!C5 -> 79474 | F12: ='P&L Assumptions'!D5 -> 86392 | G12: ='P&L Assumptions'!E5 -> 91471 | H12: ='P&L Assumptions'!F5 -> 91854 | J12: ='P&L Assumptions'!H5 -> 94150.35 | K12: ='P&L Assumptions'!I5 -> 96504.109 | L12: ='P&L Assumptions'!J5 -> 98916.711 | M12: ='P&L Assumptions'!K5 -> 101389.63 | N12: ='P&L Assumptions'!L5 -> 103924.37
C13: % Growth | E13: ='P&L Assumptions'!C6 -> 0.12934122 | F13: ='P&L Assumptions'!D6 -> 0.087047336 | G13: ='P&L Assumptions'!E6 -> 0.058790166 | H13: ='P&L Assumptions'!F6 -> 0.0041871194 | J13: ='P&L Assumptions'!H6 -> 0.025 | K13: ='P&L Assumptions'!I6 -> 0.025 | L13: ='P&L Assumptions'!J6 -> 0.025 | M13: ='P&L Assumptions'!K6 -> 0.025 | N13: ='P&L Assumptions'!L6 -> 0.025
C15: EBIT | E15: =DATA!D44 -> 221.5 | F15: =DATA!E44 -> 391.7 | G15: =DATA!F44 -> 338.9 | H15: =DATA!G44 -> 366.5 | J15: ='P&L Assumptions'!H5+'P&L Assumptions'!H11-'P&L Assumptions'!H17-'P&L Assumptions'!H23-'P&L Assumptions'!H29 -> 7322.812 | K15: ='P&L Assumptions'!I5+'P&L Assumptions'!I11-'P&L Assumptions'!I17-'P&L Assumptions'!I23-'P&L Assumptions'!I29 -> 7434.3282 | L15: ='P&L Assumptions'!J5+'P&L Assumptions'!J11-'P&L Assumptions'!J17-'P&L Assumptions'!J23-'P&L Assumptions'!J29 -> 7545.5554 | M15: ='P&L Assumptions'!K5+'P&L Assumptions'!K11-'P&L Assumptions'!K17-'P&L Assumptions'!K23-'P&L Assumptions'!K29 -> 7652.0297 | N15: ='P&L Assumptions'!L5+'P&L Assumptions'!L11-'P&L Assumptions'!L17-'P&L Assumptions'!L23-'P&L Assumptions'!L29 -> 7757.5507
C16: % of Sales | E16: =E15/(DATA!D4*1000) -> 0.002787075 | F16: =F15/(DATA!E4*1000) -> 0.0045339846 | G16: =G15/(DATA!F4*1000) -> 0.0037049994 | H16: =H15/(DATA!G4*1000) -> 0.0039900277 | J16: 0.004 | K16: 0.004 | L16: 0.004 | M16: 0.004 | N16: 0.004
C18: Taxes | E18: =DATA!D8*1000 -> 2142 | F18: =DATA!E8*1000 -> 1727 | G18: =DATA!F8*1000 -> 2262 | H18: =DATA!G8*1000 -> 2320 | J18: ='P&L Assumptions'!H49 -> 2335.882 | K18: ='P&L Assumptions'!I49 -> 2359.2408 | L18: ='P&L Assumptions'!J49 -> 2382.8332 | M18: ='P&L Assumptions'!K49 -> 2406.6615 | N18: ='P&L Assumptions'!L49 -> 2430.7281
C19: % of EBIT | E19: ='P&L Assumptions'!C50 -> 0.0091343284 | F19: ='P&L Assumptions'!D50 -> 0.0077968397 | G19: ='P&L Assumptions'!E50 -> 0.0057748277 | H19: ='P&L Assumptions'!F50 -> 0.0068456772 | J19: ='P&L Assumptions'!H50 -> 0.01 | K19: ='P&L Assumptions'!I50 -> 0.01 | L19: ='P&L Assumptions'!J50 -> 0.01 | M19: ='P&L Assumptions'!K50 -> 0.01 | N19: ='P&L Assumptions'!L50 -> 0.01
C21: EBIAT | J21: =J15-J18 -> 4986.93 | K21: =K15-K18 -> 5075.0874 | L21: =L15-L18 -> 5162.7222 | M21: =M15-M18 -> 5245.3682 | N21: =N15-N18 -> 5326.8225
C22: D&A | E22: =DATA!D9*1000 -> 3215 | F22: =DATA!E9*1000 -> 3280 | G22: =DATA!F9*1000 -> 3518 | H22: =DATA!G9*1000 -> 3815 | J22: ='P&L Assumptions'!H29 -> 3975.23 | K22: ='P&L Assumptions'!I29 -> 4146.1649 | L22: ='P&L Assumptions'!J29 -> 4324.45 | M22: ='P&L Assumptions'!K29 -> 4514.7258 | N22: ='P&L Assumptions'!L29 -> 4713.3737
C23: % of Sales | E23: ='P&L Assumptions'!C30 -> 0.040453482 | F23: =E23 -> 0.040453482 | G23: =F23 -> 0.040453482 | H23: =G23 -> 0.040453482 | J23: ='P&L Assumptions'!H30 -> 0.042 | K23: ='P&L Assumptions'!I30 -> 0.043 | L23: ='P&L Assumptions'!J30 -> 0.043 | M23: ='P&L Assumptions'!K30 -> 0.044 | N23: ='P&L Assumptions'!L30 -> 0.044
C25: CapEx | E25: =-DATA!D36*1000 -> 3269 | F25: =-DATA!E36*1000 -> 2430 | G25: =-DATA!F36*1000 -> 5495 | H25: =-DATA!G36*1000 -> 5472 | J25: ='BS and Working Capital Analysis'!I17 -> -5649.021 | K25: ='BS and Working Capital Analysis'!J17 -> -5790.2465 | L25: ='BS and Working Capital Analysis'!K17 -> -5935.0027 | M25: ='BS and Working Capital Analysis'!L17 -> -6083.3778 | N25: ='BS and Working Capital Analysis'!M17 -> -6235.4622
C26: % of Sales | E26: =E25/E12 -> 0.041132949 | F26: =F25/E12 -> 0.030576037 | G26: =G25/F12 -> 0.063605426 | H26: =H25/H12 -> 0.0595728 | J26: =J25/J12 -> -0.06 | K26: =K25/K12 -> -0.06 | L26: =L25/L12 -> -0.06 | M26: =M25/M12 -> -0.06 | N26: =N25/N12 -> -0.06
C28: Change in NWC | E28: =DATA!C37*1000 -> 3819 | F28: =DATA!D37*1000 -> -10780 | G28: =DATA!E37*1000 -> -8523 | H28: =DATA!F37*1000 -> -3009 | J28: =J29*J12 -> -5928.4395 | K28: =K29*K12 -> -3161.3306 | L28: =L29*L12 -> -6228.5667 | M28: =M29*M12 -> -4852.827 | N28: =N29*N12 -> -4974.1476
C29: % of Sales | E29: =E28/E12 -> 0.048053451 | F29: =F28/F12 -> -0.12478007 | G29: =G28/G12 -> -0.093177073 | H29: =H28/H12 -> -0.032758508 | J29: =AVERAGE(G29:H29) -> -0.06296779 | K29: =AVERAGE(H29:I29) -> -0.032758508 | L29: =AVERAGE(I29:J29) -> -0.06296779 | M29: =AVERAGE(J29:K29) -> -0.047863149 | N29: =AVERAGE(K29:L29) -> -0.047863149
C33: Unlevered Cash Flow | J33: =J21+J22+J25-J28 -> 9241.5785 | K33: =K21+K22+K25-K28 -> 6592.3364 | L33: =L21+L22+L25-L28 -> 9780.7362 | M33: =M21+M22+M25-M28 -> 8529.5432 | N33: =N21+N22+N25-N28 -> 8778.8817
C34: Discount Factor | J34: =1/(1+$K$4)^J10 -> 0.93842176 | K34: =1/(1+$K$4)^K10 -> 0.8806354 | L34: =1/(1+$K$4)^L10 -> 0.82640742 | M34: =1/(1+$K$4)^M10 -> 0.77551871 | N34: =1/(1+$K$4)^N10 -> 0.72776363
C35: Present Value of FCF | J35: =J33/($K$4+1)^J10 -> 8672.4984 | K35: =K33/($K$4+1)^K10 -> 5805.4448 | L35: =L33/($K$4+1)^L10 -> 8082.873 | M35: =M33/($K$4+1)^M10 -> 6614.8203 | N35: =N33/($K$4+1)^N10 -> 6388.9508
C38: Terminal Value | N38: =(N33*(1+K5))/(K4-K5) -> 253860.69
C39: Present Value of Terminal Value | N39: =N38/(K4+1)^N10 -> 184750.58
C40: Enterprise Value | N40: =SUM(J35:N35)+N39 -> 220315.17
C41: + Cash | N41: =DATA!G20*1000 -> 8505
C42: - Debt | N42: =DATA!G17 -> 1540.7
C43: Equity Value | N43: =N40+N41-N42 -> 227279.47
C44: Diluted Shares Oustanding | N44: =DATA!G22*1000 -> 1371
C45: Share Price | N45: =N43/N44 -> 165.77642

Sheet Assumptions
B4: ASSUMPTIONS ->

Sheet P&L Assumptions
B1: P&L assumptions
B4: $ in millions | C4: FY21 Actual | D4: FY22 Actual | E4: FY23 Actual | F4: FY24 Actual | H4: FY25 Forecast | I4: FY26 Forecast | J4: FY27 Forecast | K4: FY28 Forecast | L4: FY29 Forecast | N4: Notes
B5: Revenues | C5: 79474 | D5: 86392 | E5: 91471 | F5: 91854 | H5: =F5*(H6+1) -> 94150.35 | I5: =H5*(1+I6) -> 96504.109 | J5: =I5*(1+J6) -> 98916.711 | K5: =J5*(1+K6) -> 101389.63 | L5: =K5*(1+L6) -> 103924.37 | M5: done | N5: Expected Revenue Growth is 2.5%.
B6: y-o-y growth% | C6: =(DATA!D4-DATA!C4)/DATA!C4 -> 0.12934122 | D6: =(DATA!E4-DATA!D4)/DATA!D4 -> 0.087047336 | E6: =(DATA!F4-DATA!E4)/DATA!E4 -> 0.058790166 | F6: =(DATA!G4-DATA!F4)/DATA!F4 -> 0.0041871194 | H6: 0.025 | I6: 0.025 | J6: 0.025 | K6: 0.025 | L6: 0.025 | M6: done
B7: Case 1: | H7: 0.04 | I7: 0.04 | J7: 0.04 | K7: 0.04 | L7: 0.04 | M7: done
B8: Case 2: | H8: 0.025 | I8: 0.025 | J8: 0.025 | K8: 0.025 | L8: 0.025 | M8: done
B9: Case 3: | H9: 0.01 | I9: 0.01 | J9: 0.01 | K9: 0.01 | L9: 0.01 | M9: done
M10: done
B11: Other Revenues | C11: 0 | D11: 0 | E11: 0 | F11: 0 | H11: =F11*(1+H12) -> 0 | I11: =H11*(1+I12) -> 0 | J11: =I11*(1+J12) -> 0 | K11: =J11*(1+K12) -> 0 | L11: =K11*(1+L12) -> 0 | M11: done | N11: Not Specified
B12: y-o-y growth% | H12: =CHOOSE(DCF!$N$4,H13,H14,H15) -> 0 | I12: =CHOOSE(DCF!$N$4,I13,I14,I15) -> 0 | J12: =CHOOSE(DCF!$N$4,J13,J14,J15) -> 0 | K12: =CHOOSE(DCF!$N$4,K13,K14,K15) -> 0 | L12: =CHOOSE(DCF!$N$4,L13,L14,L15) -> 0 | M12: done
B13: Case 1: | H13: 0 | I13: 0 | J13: 0 | K13: 0 | L13: 0 | M13: done
B14: Case 2: | H14: 0 | I14: 0 | J14: 0 | K14: 0 | L14: 0 | M14: done
B15: Case 3: | H15: 0 | I15: 0 | J15: 0 | K15: 0 | L15: 0 | M15: done
M16: done
B17: Cost of goods sold | C17: =DATA!D5*1000 -> 37075 | D17: =DATA!E5*1000 -> 40576 | E17: =DATA!F5*1000 -> 41881 | F17: =DATA!G5*1000 -> 41744 | H17: =H18*H5 -> 45192.168 | I17: =I18*I5 -> 46321.972 | J17: =J18*J5 -> 47480.022 | K17: =K18*K5 -> 48667.022 | L17: =L18*L5 -> 49883.698 | M17: done | N17: Average of past 4-5 years
B18: % of Revenues | C18: =C17/C5 -> 0.46650477 | D18: =D17/C5 -> 0.51055691 | E18: =E17/D5 -> 0.48477868 | F18: =F17/F5 -> 0.45446034 | H18: =CHOOSE(DCF!$N$4,H19,H20,H21) -> 0.48 | I18: =CHOOSE(DCF!$N$4,I19,I20,I21) -> 0.48 | J18: =CHOOSE(DCF!$N$4,J19,J20,J21) -> 0.48 | K18: =CHOOSE(DCF!$N$4,K19,K20,K21) -> 0.48 | L18: =CHOOSE(DCF!$N$4,L19,L20,L21) -> 0.48 | M18: done
B19: Case 1: | H19: 0.45 | I19: 0.45 | J19: 0.45 | K19: 0.45 | L19: 0.45 | M19: done
B20: Case 2: | H20: 0.48 | I20: 0.48 | J20: 0.48 | K20: 0.48 | L20: 0.48 | M20: done
B21: Case 3: | H21: 0.51 | I21: 0.51 | J21: 0.51 | K21: 0.51 | L21: 0.51 | M21: done
M22: done
B23: Operating Expenses | C23: =DATA!D6*1000 -> 31237 | D23: =DATA!E6*1000 -> 34459 | E23: =DATA!F6*1000 -> 36677 | F23: =DATA!G6*1000 -> 37190 | H23: =H5*H24 -> 37660.14 | I23: =I5*I24 -> 38601.643 | J23: =J5*J24 -> 39566.685 | K23: =K5*K24 -> 40555.852 | L23: =L5*L24 -> 41569.748 | M23: done | N23: Expected to stay fairly the same - potential positive benefit from their investments in distribution centers
B24: % of Revenues | C24: =C23/C5 -> 0.39304678 | D24: =D23/D5 -> 0.39886795 | E24: =E23/E5 -> 0.40096861 | F24: =F23/F5 -> 0.40488166 | H24: =CHOOSE(DCF!$N$4,H25,H26,H27) -> 0.4 | I24: =CHOOSE(DCF!$N$4,I25,I26,I27) -> 0.4 | J24: =CHOOSE(DCF!$N$4,J25,J26,J27) -> 0.4 | K24: =CHOOSE(DCF!$N$4,K25,K26,K27) -> 0.4 | L24: =CHOOSE(DCF!$N$4,L25,L26,L27) -> 0.4 | M24: done
B25: Case 1: | H25: 0.395 | I25: 0.395 | J25: 0.395 | K25: 0.395 | L25: 0.395 | M25: done
B26: Case 2: | H26: 0.4 | I26: 0.4 | J26: 0.4 | K26: 0.4 | L26: 0.4 | M26: done
B27: Case 3: | H27: 0.405 | I27: 0.405 | J27: 0.405 | K27: 0.405 | L27: 0.405 | M27: done
M28: done
B29: D&A | C29: =DATA!D9*1000 -> 3215 | D29: =DATA!E9*1000 -> 3280 | E29: =DATA!F9*1000 -> 3518 | F29: =DATA!G9*1000 -> 3815 | H29: =F29*(1+H30) -> 3975.23 | I29: =H29*(1+I30) -> 4146.1649 | J29: =I29*(1+J30) -> 4324.45 | K29: =J29*(1+K30) -> 4514.7258 | L29: =K29*(1+L30) -> 4713.3737 | M29: done | N29: In line with histroical figures
B30: % of Revenues | C30: =C29/C5 -> 0.040453482 | D30: =D29/C5 -> 0.041271359 | E30: =E29/D5 -> 0.040721363 | F30: =F29/F5 -> 0.041533303 | H30: =CHOOSE(DCF!$N$4,H31,H32,H33) -> 0.042 | I30: =CHOOSE(DCF!$N$4,I31,I32,I33) -> 0.043 | J30: =CHOOSE(DCF!$N$4,J31,J32,J33) -> 0.043 | K30: =CHOOSE(DCF!$N$4,K31,K32,K33) -> 0.044 | L30: =CHOOSE(DCF!$N$4,L31,L32,L33) -> 0.044 | M30: done
B31: Case 1: | H31: 0.042 | I31: 0.043 | J31: 0.043 | K31: 0.044 | L31: 0.044 | M31: done
B32: Case 2: | H32: 0.042 | I32: 0.043 | J32: 0.043 | K32: 0.044 | L32: 0.044 | M32: done
B33: Case 3: | H33: 0.042 | I33: 0.043 | J33: 0.043 | K33: 0.044 | L33: 0.044 | M33: done
I34: 0.043 | J34: 0.043 | M34: done
M35: done
M36: done
B37: Interest expenses | C37: =DATA!D10*1000 -> 1863 | D37: =DATA!E10*1000 -> 939 | E37: =DATA!F10*1000 -> 819 | F37: =DATA!G10*1000 -> 919 | H37: =F37*(1+H38) -> 1029.28 | I37: =H37*(1+I38) -> 1152.7936 | J37: =I37*(1+J38) -> 1291.1288 | K37: =J37*(1+K38) -> 1446.0643 | L37: =K37*(1+L38) -> 1619.592 | M37: done | N37: Flat
B38: y-o-y % growth | C38: =(C37-(DATA!C10*1000))/'P&L Assumptions'!C37 -> 0.39452496 | D38: =(D37-C37)/C37 -> -0.49597424 | E38: =(E37-D37)/D37 -> -0.12779553 | F38: =(F37-E37)/E37 -> 0.12210012 | H38: =CHOOSE(DCF!$N$4,H39,H40,H41) -> 0.12 | I38: =CHOOSE(DCF!$N$4,I39,I40,I41) -> 0.12 | J38: =CHOOSE(DCF!$N$4,J39,J40,J41) -> 0.12 | K38: =CHOOSE(DCF!$N$4,K39,K40,K41) -> 0.12 | L38: =CHOOSE(DCF!$N$4,L39,L40,L41) -> 0.12 | M38: done
B39: Case 1: | H39: 0.06 | I39: 0.06 | J39: 0.06 | K39: 0.06 | L39: 0.06 | M39: done
B40: Case 2: | H40: 0.12 | I40: 0.12 | J40: 0.12 | K40: 0.12 | L40: 0.12 | M40: done
B41: Case 3: | H41: 0.24 | I41: 0.24 | J41: 0.24 | K41: 0.24 | L41: 0.24 | M41: done
M42: done
...

Sheet BS and Working Capital Analysis
B1: BS/Working Capital assumptions
B4: $ in millions | C4: FY20 Actual | D4: FY21 Actual | E4: FY22 Actual | F4: FY23 Actual | G4: FY24 Actual | I4: FY23 Forecast | J4: FY24 Forecast | K4: FY25 Forecast | L4: FY26 Forecast | M4: FY27 Forecast
B5: Accounts Receivables | C5: =DATA!C24 -> 0.109 | D5: =DATA!D24 -> 0.111 | E5: =DATA!E24 -> 0.202 | F5: =DATA!F24 -> 0.2 | G5: =DATA!G24 -> 0.111 | I5: =I6*'P&L Assumptions'!H5/360 -> 113.775 | J5: =J6*'P&L Assumptions'!I5/360 -> 116.61937 | K5: =K6*'P&L Assumptions'!J5/360 -> 119.53486 | L5: =L6*'P&L Assumptions'!K5/360 -> 122.52323 | M5: =M6*'P&L Assumptions'!L5/360 -> 125.58631
B6: Days Receivable | C6: =(C5/DATA!C4)*360 -> 0.55760814 | D6: =(D5/DATA!D4)*360 -> 0.50280595 | E6: =(E5/DATA!E4)*(360) -> 0.84174461 | F6: =(F5/DATA!F4)*(360) -> 0.78713472 | G6: =(G5/DATA!G4)*(360) -> 0.43503821 | I6: =$G$6 -> 0.43503821 | J6: =$G$6 -> 0.43503821 | K6: =$G$6 -> 0.43503821 | L6: =$G$6 -> 0.43503821 | M6: =$G$6 -> 0.43503821
B8: Inventory | C8: =DATA!C25 -> 4.172 | D8: =DATA!D25 -> 4.347 | E8: =DATA!E25 -> 5.222 | F8: =DATA!F25 -> 5.334 | G8: =DATA!G25 -> 5.306 | I8: =I9*'P&L Assumptions'!H17/360 -> 5744.29 | J8: =J9*'P&L Assumptions'!I17/360 -> 5887.8973 | K8: =K9*'P&L Assumptions'!J17/360 -> 6035.0947 | L8: =L9*'P&L Assumptions'!K17/360 -> 6185.9721 | M8: =M9*'P&L Assumptions'!L17/360 -> 6340.6214
B9: Days Inventory | C9: =(C8/DATA!C5)*(360) -> 47.234645 | D9: =(D8/DATA!D5)*(360) -> 42.209575 | E9: =(E8/DATA!E5)*(360) -> 46.330836 | F9: =(F8/DATA!F5)*(360) -> 45.849908 | G9: =(G8/DATA!G5)*(360) -> 45.758911 | I9: =$G$9 -> 45.758911 | J9: =$G$9 -> 45.758911 | K9: =$G$9 -> 45.758911 | L9: =$G$9 -> 45.758911 | M9: =$G$9 -> 45.758911
B11: Accounts Payables | C11: =DATA!C23 -> 13.218 | D11: =DATA!D23 -> 14.429 | E11: =DATA!E23 -> 15.979 | F11: =DATA!F23 -> 16.925 | G11: =DATA!G23 -> 16.34 | I11: =I12*'P&L Assumptions'!H17/360 -> 17689.728 | J11: =J12*'P&L Assumptions'!I17/360 -> 18131.972 | K11: =K12*'P&L Assumptions'!J17/360 -> 18585.271 | L11: =L12*'P&L Assumptions'!K17/360 -> 19049.903 | M11: =M12*'P&L Assumptions'!L17/360 -> 19526.15
B12: Days Payable | C12: =(C11/DATA!C5)*(360) -> 149.65185 | D12: =(D11/DATA!D5)*(360) -> 140.10627 | E12: =(E11/DATA!E5)*(360) -> 141.76952 | F12: =(F11/DATA!F5)*(360) -> 145.48363 | G12: =(G11/DATA!G5)*(360) -> 140.91606 | I12: =$G$12 -> 140.91606 | J12: =$G$12 -> 140.91606 | K12: =$G$12 -> 140.91606 | L12: =$G$12 -> 140.91606 | M12: =$G$12 -> 140.91606
B14: Net Trade Cycle | C14: =C6+C9-C12 -> -101.8596 | D14: =D6+D9-D12 -> -97.39389 | E14: =E6+E9-E12 -> -94.596938 | F14: =F6+F9-F12 -> -98.846589 | G14: =G6+G9-G12 -> -94.72211 | I14: =I6+I9-I12 -> -94.72211 | J14: =J6+J9-J12 -> -94.72211 | K14: =K6+K9-K12 -> -94.72211 | L14: =L6+L9-L12 -> -94.72211 | M14: =M6+M9-M12 -> -94.72211
B17: CapEx | C17: =DATA!C36 -> -11.619 | D17: =DATA!D36 -> -3.269 | E17: =DATA!E36 -> -2.43 | F17: =DATA!F36 -> -5.495 | G17: =DATA!G36 -> -5.472 | I17: =$I$18*'P&L Assumptions'!H5 -> -5649.021 | J17: =J18*'P&L Assumptions'!I5 -> -5790.2465 | K17: =K18*'P&L Assumptions'!J5 -> -5935.0027 | L17: =L18*'P&L Assumptions'!K5 -> -6083.3778 | M17: =M18*'P&L Assumptions'!L5 -> -6235.4622
B18: % of Sales | C18: =C17/DATA!C4 -> -0.16510828 | D18: =D17/DATA!D4 -> -0.041132949 | E18: =E17/DATA!E4 -> -0.028127604 | F18: =F17/DATA!F4 -> -0.060073685 | G18: =G17/DATA!G4 -> -0.0595728 | I18: =CHOOSE(DCF!$N$4,'BS and Working Capital Analysis'!I19,'BS and Working Capital Analysis'!I20,'BS and Working Capital Analysis'!I21) -> -0.06 | J18: =CHOOSE(DCF!$N$4,'BS and Working Capital Analysis'!J19,'BS and Working Capital Analysis'!J20,'BS and Working Capital Analysis'!J21) -> -0.06 | K18: =CHOOSE(DCF!$N$4,'BS and Working Capital Analysis'!K19,'BS and Working Capital Analysis'!K20,'BS and Working Capital Analysis'!K21) -> -0.06 | L18: =CHOOSE(DCF!$N$4,'BS and Working Capital Analysis'!L19,'BS and Working Capital Analysis'!L20,'BS and Working Capital Analysis'!L21) -> -0.06 | M18: =CHOOSE(DCF!$N$4,'BS and Working Capital Analysis'!M19,'BS and Working Capital Analysis'!M20,'BS and Working Capital Analysis'!M21) -> -0.06
B19: Case 1: | I19: -0.03 | J19: -0.03 | K19: -0.03 | L19: -0.03 | M19: -0.03
B20: Case 2: | I20: -0.06 | J20: -0.06 | K20: -0.06 | L20: -0.06 | M20: -0.06
B21: Case 3: | I21: -0.09 | J21: -0.09 | K21: -0.09 | L21: -0.09 | M21: -0.09

Sheet WACC
B2: WACC
B4: WACC = (% Equity x Cost of Equity) + (% Debt x Cost of Debt x (1 -Tax rate))
B5: Cost of Equity = Risk Free Rate + (Beta x (Expected Market Return - Risk Free Rate))
B7: Debt | D7: =DATA!G19 -> 37.224 | F7: Resources
B8: % Debt | D8: =D7/D19 -> 0.671974 | F8: https://www.sec.gov/ix?doc=/Archives/edgar/data/27419/000002741923000015/tgt-20230128.htm
B9: Cost of Debt | D9: 0.0545 | E9: *
B10: Tax Rate | D10: =DATA!G11/100 -> 0.194
B12: Equity Value | D12: =DATA!G16 -> 18.171 | F12: Drivers
B13: % Equity | D13: =D12/D19 -> 0.328026 | F13: Company: | H13: PepsiCo Inc
B14: Cost of Equity (CAPM) | D14: =D15+D16*(D17-D15) -> 0.065809 | F14: Currency | H14: USD
B15: Risk Free Rate (rf) | D15: 0.04105 | F15: Domestic country | H15: United States
B16: Beta (B) | D16: 0.42 | F16: 10-year treasury yield | H16: 0.04105
B17: Expected Market Return (Erm) | D17: 0.1 | F17: Market risk premium US | H17: 5.9% assuming a 10% market return
F18: Company beta | H18: 0.42
B19: Debt + Equity | D19: =D7+D12 -> 55.395 | F19: Share Price | H19: 146.1
F20: Bond Yield
B21: WACC | D21: =(D13*D14)+((D8*D9)*(1-D10)) -> 0.051104865 | F21: Corporate tax rate | H21: 0.194
B22: Bloomberg WACC | D22: 0.085 | F22: Expected inflation | H22: 0.03

Sheet DATA
B2: Fiscal Years | C2: FY 2020 | D2: FY 2021 | E2: FY 2022 | F2: FY 2023 | G2: FY 2024
B3: Income Statement Items
B4: Total Revenues | C4: 70.372 | D4: 79.474 | E4: 86.392 | F4: 91.471 | G4: 91.854 | H4: Done
B5: Cost Of Revenues | C5: 31.797 | D5: 37.075 | E5: 40.576 | F5: 41.881 | G5: 41.744 | H5: Done
B6: Selling General & Admin Expenses / Total | C6: 28.453 | D6: 31.237 | E6: 34.459 | F6: 36.677 | G6: 37.19 | H6: Done
B7: Other Operating Expenses | C7: 42 | D7: 0 | E7: -155 | F7: 927 | G7: 33 | H7: Done
B8: Income Tax Expense | C8: 1.894 | D8: 2.142 | E8: 1.727 | F8: 2.262 | G8: 2.32 | H8: Done
B9: Depreciation & Amortization | C9: =13.106-10.08 -> 3.026 | D9: =14.377-11.162 -> 3.215 | E9: =14.792-11.512 -> 3.28 | F9: =15.504-11.986 -> 3.518 | G9: =16.702-12.887 -> 3.815 | H9: Done
B10: Interest Expense / Total | C10: 1.128 | D10: 1.863 | E10: 0.939 | F10: 0.819 | G10: 0.919 | H10: Done
B11: Effective Tax Rate - (Ratio) | C11: 20.9 | D11: 21.8 | E11: 16.1 | F11: 19.8 | G11: 19.4 | H11: Done
B13: Balance Sheet
B14: Total Current Assets | C14: 23.001 | D14: 21.783 | E14: 21.539 | F14: 26.95 | G14: 25.826 | H14: Done
B15: Total Current Liabilities | C15: 23.372 | D15: 26.22 | E15: 26.785 | F15: 31.647 | G15: 31.536 | H15: Done
B16: Total Equity | C16: 13.552 | D16: 16.151 | E16: 17.273 | F16: 18.637 | G16: 18.171 | H16: Done
B17: Total Debt | C17: 580.1 | D17: 1741.6 | E17: 1478.1 | F17: 1513.5 | G17: 1540.7
B18: Short Term Debt | C18: - | D18: 1.7 | E18: 5.7 | F18: 5.1 | G18: -
B19: Long Term Debt | C19: 40.37 | D19: 36.026 | E19: 35.657 | F19: 37.595 | G19: 37.224 | H19: Done
B20: Cash And Equivalents | C20: 8.185 | D20: 5.596 | E20: 4.954 | F20: 9.711 | G20: 8.505 | H20: Done
B21: Shares Outstanding / Current | E21: 1387000000 | F21: 1383000000 | G21: 1.378
B22: Diluted Weighted Average Shares Outstanding | G22: 1.371
B23: Accounts Payable / Total | C23: 13.218 | D23: 14.429 | E23: 15.979 | F23: 16.925 | G23: 16.34 | H23: Done
B24: Total Receivables | C24: 0.109 | D24: 0.111 | E24: 0.202 | F24: 0.2 | G24: 0.111 | H24: Done
B25: Inventory | C25: 4.172 | D25: 4.347 | E25: 5.222 | F25: 5.334 | G25: 5.306 | H25: Done
B26: Restricted Cash | C26: 0 | D26: 0 | E26: 0 | F26: 0 | G26: 0 | H26: Done
B27: Prepaid Expenses | C27: 0 | D27: 0 | E27: 0 | F27: 0 | G27: 0 | H27: Done
B28: Other Current Assets / Total | C28: 874 | D28: 980 | E28: 806 | F28: 798 | G28: 921 | H28: Done
B29: Accrued Expenses / Total | C29: 13.218 | D29: 14.429 | E29: 15.979 | F29: 16.925 | G29: 16.34 | H29: Done
B30: Unearned Revenue Current / Total | H30: Done
B31: Current Portion of Leases | C31: 3.818 | D31: 4.318 | E31: 3.579 | F31: 4.48 | G31: 4.646 | H31: Done
B32: Net Property Plant And Equipment | C32: 23.039 | D32: 24.472 | E32: 26.664 | F32: 29.944 | G32: 31.391 | H32: Done
B34: Cash Flow Statement | H34: Done
B35: Cash Flow from Operating Activities, Indirect | C35: 10.613 | D35: 11.616 | E35: 10.811 | F35: 13.442 | G35: 12.507 | H35: Done
B36: Cash Flow from Investing Activities | C36: -11.619 | D36: -3.269 | E36: -2.43 | F36: -5.495 | G36: -5.472 | H36: Done
B37: Cash Flow from Financing Activities | C37: 3.819 | D37: -10.78 | E37: -8.523 | F37: -3.009 | G37: -7.556 | H37: Done
B38: Cash and Cash Equivalents, End of Period | C38: 8.254 | D38: 5.707 | E38: 5.1 | F38: 9.761 | G38: 8.553 | H38: Done
B41: Supplemental Items
B42: EBITDA | C42: 345.3 | D42: 344.3 | E42: 518.2 | F42: 464.4 | G42: 493.5
B43: EBITA | C43: 235.9 | D43: 221.7 | E43: 391.3 | F43: 338.9 | G43: 366.5
B44: EBIT | C44: 234.5 | D44: 221.5 | E44: 391.7 | F44: 338.9 | G44: 366.5
B45: Effective Tax Rate - (Ratio) | C45: 19.03 | D45: 23.72 | E45: 23.73 | F45: 24.27 | G45: 25.23
...

Sheet Statements
B6: Statements ->
